<?xml version="1.0" ?>
<robot name="turtlebot3_waffle" xmlns:xacro="http://ros.org/wiki/xacro">

  <!-- 색상 정의 -->
  <material name="black"><color rgba="0.0 0.0 0.0 1.0"/></material>
  <material name="dark"><color rgba="0.3 0.3 0.3 1.0"/></material>
  <material name="light_black"><color rgba="0.4 0.4 0.4 1.0"/></material>
  <material name="blue"><color rgba="0.0 0.0 0.8 1.0"/></material>
  <material name="green"><color rgba="0.0 0.8 0.0 1.0"/></material>
  <material name="grey"><color rgba="0.5 0.5 0.5 1.0"/></material>
  <material name="orange"><color rgba="1.0 0.4235 0.0392 1.0"/></material>
  <material name="brown"><color rgba="0.8706 0.8118 0.7647 1.0"/></material>
  <material name="red"><color rgba="0.8 0.0 0.0 1.0"/></material>
  <material name="white"><color rgba="1.0 1.0 1.0 1.0"/></material>

  <!-- Base -->
  <link name="base_footprint"/>

  <joint name="base_joint" type="fixed">
    <parent link="base_footprint"/>
    <child link="base_link"/>
    <origin xyz="0 0 0.020" rpy="0 0 0"/>
  </joint>

  <link name="base_link">
    <visual>
      <origin xyz="-0.128 0 0.0" rpy="0 0 0"/>
      <geometry>
        <mesh filename="package://turtlebot3_description/meshes/bases/waffle_base.stl" scale="0.002 0.002 0.002"/>
      </geometry>
      <material name="light_black"/>
    </visual>
    <collision>
      <origin xyz="-0.128 0 0.094" rpy="0 0 0"/>
      <geometry>
        <box size="0.532 0.532 0.188"/>
      </geometry>
    </collision>
    <inertial>
      <origin xyz="-0.06 0 0.06"/>
      <mass value="6.0"/>
      <inertia ixx="0.060" ixy="0.0" ixz="0.0"
               iyy="0.060" iyz="0.0" izz="0.060"/>
    </inertial>
  </link>

  <!-- Left Wheel -->
  <joint name="wheel_left_joint" type="continuous">
    <parent link="base_link"/>
    <child link="wheel_left_link"/>
    <origin xyz="0.0 0.288 0.046" rpy="-1.57 0 0"/>
    <axis xyz="0 0 1"/>
  </joint>

  <link name="wheel_left_link">
    <visual>
      <origin xyz="0 0 0" rpy="1.57 0 0"/>
      <geometry>
        <mesh filename="package://turtlebot3_description/meshes/wheels/left_tire.stl" scale="0.002 0.002 0.002"/>
      </geometry>
      <material name="dark"/>
    </visual>
    <collision>
      <origin xyz="0 0 0" rpy="0 0 0"/>
      <geometry>
        <cylinder length="0.036" radius="0.066"/>
      </geometry>
    </collision>
    <inertial>
      <origin xyz="0 0 0"/>
      <mass value="0.4"/>
      <inertia ixx="0.004" ixy="0.0" ixz="0.0"
               iyy="0.004" iyz="0.0" izz="0.004"/>
    </inertial>
  </link>

  <!-- Right Wheel -->
  <joint name="wheel_right_joint" type="continuous">
    <parent link="base_link"/>
    <child link="wheel_right_link"/>
    <origin xyz="0.0 -0.288 0.046" rpy="-1.57 0 0"/>
    <axis xyz="0 0 1"/>
  </joint>

  <link name="wheel_right_link">
    <visual>
      <origin xyz="0 0 0" rpy="1.57 0 0"/>
      <geometry>
        <mesh filename="package://turtlebot3_description/meshes/wheels/right_tire.stl" scale="0.002 0.002 0.002"/>
      </geometry>
      <material name="dark"/>
    </visual>
    <collision>
      <origin xyz="0 0 0" rpy="0 0 0"/>
      <geometry>
        <cylinder length="0.036" radius="0.066"/>
      </geometry>
    </collision>
    <inertial>
      <origin xyz="0 0 0"/>
      <mass value="0.4"/>
      <inertia ixx="0.004" ixy="0.0" ixz="0.0"
               iyy="0.004" iyz="0.0" izz="0.004"/>
    </inertial>
  </link>

  <!-- Caster Wheels -->
  <joint name="caster_back_right_joint" type="fixed">
    <parent link="base_link"/>
    <child link="caster_back_right_link"/>
    <origin xyz="-0.354 -0.128 -0.008" rpy="-1.57 0 0"/>
  </joint>

  <link name="caster_back_right_link">
    <inertial>
      <origin xyz="0 0 0"/>
      <mass value="0.04"/>
      <inertia ixx="0.0004" ixy="0.0" ixz="0.0"
               iyy="0.0004" iyz="0.0" izz="0.0004"/>
    </inertial>
  </link>

  <joint name="caster_back_left_joint" type="fixed">
    <parent link="base_link"/>
    <child link="caster_back_left_link"/>
    <origin xyz="-0.354 0.128 -0.008" rpy="-1.57 0 0"/>
  </joint>

  <link name="caster_back_left_link">
    <inertial>
      <origin xyz="0 0 0"/>
      <mass value="0.04"/>
      <inertia ixx="0.0004" ixy="0.0" ixz="0.0"
               iyy="0.0004" iyz="0.0" izz="0.0004"/>
    </inertial>
  </link>

  <!-- 2D LiDAR -->
  <joint name="scan_joint" type="fixed">
    <parent link="base_link"/>
    <child link="base_scan"/>
    <origin xyz="-0.128 0 0.30" rpy="0 0 0"/>
  </joint>

  <link name="base_scan">
    <visual>
      <origin xyz="0 0 0" rpy="0 0 0"/>
      <geometry>
        <cylinder length="0.063" radius="0.11"/>
      </geometry>
      <material name="dark"/>
    </visual>
    <inertial>
      <origin xyz="0 0 0"/>
      <mass value="0.456"/>
      <inertia ixx="0.004" ixy="0.0" ixz="0.0"
               iyy="0.004" iyz="0.0" izz="0.004"/>
    </inertial>
  </link>

  <!-- 2D LiDAR Gazebo Plugin -->
  <gazebo reference="base_scan">
    <sensor type="ray" name="lds_lfcd_sensor">
      <pose>0 0 0 0 0 0</pose>
      <visualize>false</visualize>
      <update_rate>5</update_rate>
      <ray>
        <scan>
          <horizontal>
            <samples>360</samples>
            <resolution>1</resolution>
            <min_angle>0.0</min_angle>
            <max_angle>6.28319</max_angle>
          </horizontal>
        </scan>
        <range>
          <min>1.0</min>
          <max>5.0</max>
          <resolution>0.015</resolution>
        </range>
        <noise>
          <type>gaussian</type>
          <mean>0.0</mean>
          <stddev>0.01</stddev>
        </noise>
      </ray>
      <plugin name="gazebo_ros_lds_lfcd_controller" filename="libgazebo_ros_ray_sensor.so">
        <ros>
          <remapping>~/out:=/scan</remapping>
        </ros>
        <output_type>sensor_msgs/LaserScan</output_type>
        <frame_name>base_scan</frame_name>
      </plugin>
    </sensor>
  </gazebo>

  <!-- Depth Camera -->
  <joint name="depth_camera_joint" type="fixed">
    <parent link="base_link"/>
    <child link="depth_camera_link"/>
    <origin xyz="0.146 0 0.168" rpy="0 0.1 1.5708"/>
  </joint>

  <link name="depth_camera_link">
    <visual>
      <origin xyz="0 0 0" rpy="0 0 0"/>
      <geometry>
        <box size="0.05 0.18 0.05"/>
      </geometry>
      <material name="black"/>
    </visual>
    <inertial>
      <origin xyz="0 0 0"/>
      <mass value="0.4"/>
      <inertia ixx="0.0004" ixy="0.0" ixz="0.0"
               iyy="0.0004" iyz="0.0" izz="0.0004"/>
    </inertial>
  </link>

  <gazebo reference="depth_camera_link">
    <sensor type="depth" name="depth_camera_sensor">
      <update_rate>30.0</update_rate>
      <camera>
        <horizontal_fov>1.047198</horizontal_fov>
        <image>
          <width>640</width>
          <height>480</height>
          <format>R8G8B8</format>
        </image>
        <clip>
          <near>0.1</near>
          <far>10.0</far>
        </clip>
      </camera>

      <plugin name="depth_camera_controller" filename="libgazebo_ros_camera.so">
        <ros>
          <namespace>/depth_camera</namespace>
          <remapping>image_raw:=rgb/image_raw</remapping>
          <remapping>image_depth:=depth/image_raw</remapping>
          <remapping>camera_info:=rgb/camera_info</remapping>
          <remapping>depth/camera_info:=depth/camera_info</remapping>
          <remapping>points:=depth/points</remapping>
        </ros>
        <camera_name>depth_camera</camera_name>
        <frame_name>depth_camera_link</frame_name>
        <hack_baseline>0.14</hack_baseline>
        <min_depth>0.1</min_depth>
        <max_depth>10.0</max_depth>
      </plugin>
    </sensor>
  </gazebo>

  <!-- 3D LiDAR (Velodyne) -->
  <joint name="velodyne_joint" type="fixed">
    <parent link="base_link"/>
    <child link="velodyne_link"/>
    <origin xyz="0 0 0.20" rpy="0 0 0"/>
  </joint>

  <link name="velodyne_link">
    <visual>
      <origin xyz="0 0 0" rpy="0 0 0"/>
      <geometry>
        <cylinder length="0.14" radius="0.10"/>
      </geometry>
      <material name="black"/>
    </visual>
    <inertial>
      <origin xyz="0 0 0"/>
      <mass value="2.0"/>
      <inertia ixx="0.004" ixy="0.0" ixz="0.0"
               iyy="0.004" iyz="0.0" izz="0.004"/>
    </inertial>
  </link>

  <!-- 3D LiDAR Gazebo Plugin -->
  <gazebo reference="velodyne_link">
    <sensor type="ray" name="velodyne_sensor">
      <pose>0 0 0 0 0 0</pose>
      <visualize>false</visualize>
      <update_rate>10</update_rate>
      <ray>
        <scan>
          <horizontal>
            <samples>440</samples>
            <resolution>1</resolution>
            <min_angle>-3.14159</min_angle>
            <max_angle>3.14159</max_angle>
          </horizontal>
          <vertical>
            <samples>16</samples>
            <resolution>1</resolution>
            <min_angle>-0.261799</min_angle>
            <max_angle>0.261799</max_angle>
          </vertical>
        </scan>
        <range>
          <min>1.0</min>
          <max>30.0</max>
          <resolution>0.01</resolution>
        </range>
        <noise>
          <type>gaussian</type>
          <mean>0.0</mean>
          <stddev>0.005</stddev>
        </noise>
      </ray>
      <plugin name="gazebo_ros_velodyne" filename="libgazebo_ros_ray_sensor.so">
        <ros>
          <remapping>~/out:=/velodyne_points</remapping>
        </ros>
        <output_type>sensor_msgs/PointCloud2</output_type>
        <frame_name>velodyne_link</frame_name>
      </plugin>
    </sensor>
  </gazebo>

  <!-- Diff Drive Plugin -->
  <gazebo>
    <plugin name="diff_drive" filename="libgazebo_ros_diff_drive.so">
      <update_rate>30</update_rate>
      <left_joint>wheel_left_joint</left_joint>
      <right_joint>wheel_right_joint</right_joint>
      <wheel_separation>0.576</wheel_separation>
      <wheel_diameter>0.132</wheel_diameter>
      <max_wheel_torque>40</max_wheel_torque>
      <max_wheel_acceleration>1.0</max_wheel_acceleration>
      <publish_odom>true</publish_odom>
      <publish_odom_tf>true</publish_odom_tf>
      <publish_wheel_tf>false</publish_wheel_tf>
      <odometry_frame>odom</odometry_frame>
      <robot_base_frame>base_footprint</robot_base_frame>
    </plugin>
  </gazebo>

</robot>
